Workbook

Sheet Cover
B2: LEVERAGED BUYOUT ANALYSIS Dollar General Corporation (NYSE: DG)
B5: Discount Retail | ~20,000 Stores | Prepared: February 26, 2026
B7: KEY RETURNS SUMMARY
B8: IRR | C8: 22.5%
B9: MOIC | C9: 3.37x
B10: Entry EV ($M) | C10: $37,107
B11: Equity Invested ($M) | C11: $16,751
B12: Exit EV ($M) | C12: $71,372
B13: Exit Equity ($M) | C13: $56,480
B14: Hold Period | C14: 6 years
B15: Entry EV/EBITDA | C15: 10.5x
B16: Exit EV/EBITDA | C16: 12.5x
B17: Entry Leverage | C17: 6.1x
B19: TRANSACTION OVERVIEW
B20: Target | C20: Dollar General Corporation
B21: Sector | C21: Consumer Discretionary — Discount Retail
B22: LTM Revenue ($M) | C22: $37,844
B23: LTM EBITDA ($M) | C23: $3,534
B24: LTM EBITDA Margin | C24: 9.3%
B25: Total New Debt ($M) | C25: $21,500
B26: Sponsor Equity ($M) | C26: $16,751
B27: Equity / Total Cap. | C27: 43.8%
B30: CONFIDENTIAL — For Discussion Purposes Only. All values USD millions unless noted. ‡ Interest Expense is computed by an iterative debt engine and is a fixed input to the P&L.

Sheet Assumptions
B1: DEAL ASSUMPTIONS
B3: 1. ENTRY / TRANSACTION
B4: LTM EBITDA ($M) | C4: 3534
B5: Entry EV/EBITDA (x) | C5: 10.5
B6: Entry EV ($M) | C6: 37107
B7: Existing Net Debt ($M) | C7: 6512
B8: Total New Debt ($M) | C8: 21500
B9: Sponsor Equity ($M) | C9: 16751.089
B10: Entry Gross Leverage (x) | C10: 6.0837578
B11: Hold Period (years) | C11: 6
B12: Exit EV/EBITDA (x) | C12: 12.5
B13: Tax Rate | C13: 0.228
B14: Cash Sweep (%) | C14: 1
B15: Min Cash Balance ($M) | C15: 300
B17: 2. DEBT STRUCTURE
B18: Tranche | C18: Principal ($M) | D18: Rate Type | E18: All-In Rate | F18: Term (yrs) | G18: Amort % | H18: OID %
B19: Revolver | C19: 500 | D19: SOFR + 2% | E19: 0.078 | F19: 5 | G19: 0 | H19: 0.005
B20: Term Loan A | C20: 4000 | D20: SOFR + 3% | E20: 0.0805 | F20: 5 | G20: 0.05 | H20: 0.01
B21: Term Loan B | C21: 8000 | D21: SOFR + 4% | E21: 0.093 | F21: 7 | G21: 0.01 | H21: 0.02
B22: Senior Secured Notes | C22: 5500 | D22: Fixed | E22: 0.0725 | F22: 8 | G22: 0 | H22: 0.015
B23: High Yield Notes | C23: 3500 | D23: Fixed | E23: 0.09 | F23: 10 | G23: 0 | H23: 0.02
B25: 3. OPERATING PROJECTIONS (BY YEAR)
B26: Driver | C26: Year 1 | D26: Year 2 | E26: Year 3 | F26: Year 4 | G26: Year 5 | H26: Year 6
B27: Revenue Growth (%) | C27: 0.045 | D27: 0.048 | E27: 0.051 | F27: 0.054 | G27: 0.057 | H27: 0.06
B28: EBITDA Margin (%) | C28: 0.098 | D28: 0.1006 | E28: 0.1032 | F28: 0.1058 | G28: 0.1084 | H28: 0.111
B29: D&A (% Revenue) | C29: 0.0355 | D29: 0.0345 | E29: 0.0335 | F29: 0.0325 | G29: 0.0315 | H29: 0.0305
B30: CapEx (% Revenue) | C30: 0.041 | D30: 0.0395 | E30: 0.038 | F30: 0.0365 | G30: 0.035 | H30: 0.0335

Sheet Sources & Uses
B1: SOURCES & USES OF FUNDS
B3: SOURCES | C3: Amount ($M) | D3: % Total | F3: USES | G3: Amount ($M) | H3: % Total
B4: Revolver (SOFR+250bps, 5yr) | C4: 500 | D4: 1.3% | F4: Purchase Equity (EV – Net Debt) | G4: 30595 | H4: 80.0%
B5: Term Loan A (SOFR+275bps, 5yr) | C5: 4000 | D5: 10.5% | F5: Repay Existing Gross Debt | G5: 6797 | H5: 17.8%
B6: Term Loan B (SOFR+400bps, 7yr) | C6: 8000 | D6: 20.9% | F6: M&A Advisory & Legal Fees | G6: 204.1 | H6: 0.5%
B7: Senior Secured Notes (7.25% fixed, 8yr) | C7: 5500 | D7: 14.4% | F7: Financing Fees / OID | G7: 355 | H7: 0.9%
B8: High Yield Notes (9.00% fixed, 10yr) | C8: 3500 | D8: 9.2% | F8: Cash to Balance Sheet | G8: 300 | H8: 0.8%
B9: Sponsor Equity | C9: 16751.089 | D9: 43.8% | F9: Total Uses | G9: =SUM(G4:G8) -> 38251.1 | H9: 100.0%
B10: Total Sources | C10: =SUM(C4:C9) -> 38251.088 | D10: 100.0%
B13: Entry Leverage: 6.1x | Net Leverage: 6.0x | Equity / Total Cap: 43.8%

Sheet Income Statement
B1: PROJECTED INCOME STATEMENT ($M)
B3: Line Item | C3: Year 1 | D3: Year 2 | E3: Year 3 | F3: Year 4 | G3: Year 5 | H3: Year 6
B4: REVENUE & MARGIN DRIVERS ← editable inputs
B5: Entry LTM Revenue ($M) | C5: 37844
B6: Revenue Growth (%) | C6: 0.045 | D6: 0.048 | E6: 0.051 | F6: 0.054 | G6: 0.057 | H6: 0.06
B7: EBITDA Margin (%) | C7: 0.098 | D7: 0.1006 | E7: 0.1032 | F7: 0.1058 | G7: 0.1084 | H7: 0.111
B8: D&A (% Revenue) | C8: 0.0355 | D8: 0.0345 | E8: 0.0335 | F8: 0.0325 | G8: 0.0315 | H8: 0.0305
B9: Gross Margin (%) | C9: 0.304 | D9: 0.306 | E9: 0.308 | F9: 0.31 | G9: 0.312 | H9: 0.314
B10: Tax Rate | C10: 0.228 | D10: =$C$10 -> 0.228 | E10: =$C$10 -> 0.228 | F10: =$C$10 -> 0.228 | G10: =$C$10 -> 0.228 | H10: =$C$10 -> 0.228
B11: Annual Mgmt Fee ($M) | C11: 20 | D11: 20 | E11: 20 | F11: 20 | G11: 20 | H11: 20
B13: PROJECTED P&L (formulas reference driver block above)
B14: Revenue | C14: =$C$5*(1+C6) -> 39546.98 | D14: =C14*(1+D6) -> 41445.235 | E14: =D14*(1+E6) -> 43558.942 | F14: =E14*(1+F6) -> 45911.125 | G14: =F14*(1+G6) -> 48528.059 | H14: =G14*(1+H6) -> 51439.743
B15: COGS | C15: =C14*(1-C9) -> 27524.698 | D15: =D14*(1-D9) -> 28762.993 | E15: =E14*(1-E9) -> 30142.788 | F15: =F14*(1-F9) -> 31678.676 | G15: =G14*(1-G9) -> 33387.305 | H15: =H14*(1-H9) -> 35287.663
B16: Gross Profit | C16: =C14-C15 -> 12022.282 | D16: =D14-D15 -> 12682.242 | E16: =E14-E15 -> 13416.154 | F16: =F14-F15 -> 14232.449 | G16: =G14-G15 -> 15140.754 | H16: =H14-H15 -> 16152.079
B17: Gross Margin | C17: =C16/C14 -> 0.304 | D17: =D16/D14 -> 0.306 | E17: =E16/E14 -> 0.308 | F17: =F16/F14 -> 0.31 | G17: =G16/G14 -> 0.312 | H17: =H16/H14 -> 0.314
B18: EBITDA | C18: =C14*C7 -> 3875.604 | D18: =D14*D7 -> 4169.3906 | E18: =E14*E7 -> 4495.2828 | F18: =F14*F7 -> 4857.397 | G18: =G14*G7 -> 5260.4416 | H18: =H14*H7 -> 5709.8114
B19: EBITDA Margin | C19: =C18/C14 -> 0.098 | D19: =D18/D14 -> 0.1006 | E19: =E18/E14 -> 0.1032 | F19: =F18/F14 -> 0.1058 | G19: =G18/G14 -> 0.1084 | H19: =H18/H14 -> 0.111
B20: Mgmt Fee | C20: =C11 -> 20 | D20: =D11 -> 20 | E20: =E11 -> 20 | F20: =F11 -> 20 | G20: =G11 -> 20 | H20: =H11 -> 20
B21: Adj EBITDA | C21: =C18+C20 -> 3895.604 | D21: =D18+D20 -> 4189.3906 | E21: =E18+E20 -> 4515.2828 | F21: =F18+F20 -> 4877.397 | G21: =G18+G20 -> 5280.4416 | H21: =H18+H20 -> 5729.8114
B22: D&A | C22: =C14*C8 -> 1403.9178 | D22: =D14*D8 -> 1429.8606 | E22: =E14*E8 -> 1459.2246 | F22: =F14*F8 -> 1492.1116 | G22: =G14*G8 -> 1528.6339 | H22: =H14*H8 -> 1568.9121
B23: EBIT | C23: =C18-C22 -> 2471.6862 | D23: =D18-D22 -> 2739.53 | E23: =E18-E22 -> 3036.0583 | F23: =F18-F22 -> 3365.2855 | G23: =G18-G22 -> 3731.8077 | H23: =H18-H22 -> 4140.8993
B24: Interest Expense ‡ | C24: 1854.5 | D24: 1819 | E24: 1761.8 | F24: 1678.5 | G24: 1564.6 | H24: 1404.9
B25: EBT | C25: =C23-C24 -> 617.18625 | D25: =D23-D24 -> 920.53004 | E25: =E23-E24 -> 1274.2583 | F25: =F23-F24 -> 1686.7855 | G25: =G23-G24 -> 2167.2077 | H25: =H23-H24 -> 2735.9993
B26: Tax | C26: =MAX(0,C25)*$C$10 -> 140.71846 | D26: =MAX(0,D25)*$C$10 -> 209.88085 | E26: =MAX(0,E25)*$C$10 -> 290.53088 | F26: =MAX(0,F25)*$C$10 -> 384.58708 | G26: =MAX(0,G25)*$C$10 -> 494.12336 | H26: =MAX(0,H25)*$C$10 -> 623.80783
B27: Net Income | C27: =C25-C26 -> 476.46778 | D27: =D25-D26 -> 710.64919 | E27: =E25-E26 -> 983.72738 | F27: =F25-F26 -> 1302.1984 | G27: =G25-G26 -> 1673.0844 | H27: =H25-H26 -> 2112.1914
B29: ‡ Interest Expense is computed by an iterative cash-sweep debt model and cannot be replicated by a simple Excel formula. All other P&L line items are formula-driven.

Sheet Cash Flow Statement
B1: PROJECTED CASH FLOW STATEMENT ($M)
B3: Line Item | C3: Year 1 | D3: Year 2 | E3: Year 3 | F3: Year 4 | G3: Year 5 | H3: Year 6
B4: Net Income | C4: ='Income Statement'!C27 -> 476.46778 | D4: ='Income Statement'!D27 -> 710.64919 | E4: ='Income Statement'!E27 -> 983.72738 | F4: ='Income Statement'!F27 -> 1302.1984 | G4: ='Income Statement'!G27 -> 1673.0844 | H4: ='Income Statement'!H27 -> 2112.1914
B5: (+) D&A | C5: ='Income Statement'!C22 -> 1403.9178 | D5: ='Income Statement'!D22 -> 1429.8606 | E5: ='Income Statement'!E22 -> 1459.2246 | F5: ='Income Statement'!F22 -> 1492.1116 | G5: ='Income Statement'!G22 -> 1528.6339 | H5: ='Income Statement'!H22 -> 1568.9121
B6: (+) DFF Amort | C6: 48.7 | D6: 48.7 | E6: 48.7 | F6: 48.7 | G6: 48.7 | H6: 48.7
B7: Δ NWC | C7: -121.6 | D7: -158.3 | E7: -176.4 | F7: -196.4 | G7: -218.5 | H7: -243
B8: Operating CF | C8: =C4+C5+C6+C7 -> 1807.4856 | D8: =D4+D5+D6+D7 -> 2030.9098 | E8: =E4+E5+E6+E7 -> 2315.2519 | F8: =F4+F5+F6+F7 -> 2646.6099 | G8: =G4+G5+G6+G7 -> 3031.9182 | H8: =H4+H5+H6+H7 -> 3486.8036
B9: (-) CapEx | C9: =-'Income Statement'!C14*0.041 -> -1621.4262 | D9: =-'Income Statement'!D14*0.0395 -> -1637.0868 | E9: =-'Income Statement'!E14*0.038 -> -1655.2398 | F9: =-'Income Statement'!F14*0.0365 -> -1675.7561 | G9: =-'Income Statement'!G14*0.035 -> -1698.4821 | H9: =-'Income Statement'!H14*0.0335 -> -1723.2314
B10: Investing CF | C10: =C9 -> -1621.4262 | D10: =D9 -> -1637.0868 | E10: =E9 -> -1655.2398 | F10: =F9 -> -1675.7561 | G10: =G9 -> -1698.4821 | H10: =H9 -> -1723.2314
B11: Free Cash Flow | C11: =C8+C10 -> 186.05939 | D11: =D8+D10 -> 393.82301 | E11: =E8+E10 -> 660.01214 | F11: =F8+F10 -> 970.85387 | G11: =G8+G10 -> 1333.4362 | H11: =H8+H10 -> 1763.5722
B12: (-) Debt Repaid | C12: -308.6 | D12: -558.3 | E12: -852.8 | F12: -1199 | G12: -1606.2 | H12: -2083
B13: (-) Mgmt Fee | C13: -20 | D13: -20 | E13: -20 | F13: -20 | G13: -20 | H13: -20
B14: Financing CF | C14: =C12+C13 -> -328.6 | D14: =D12+D13 -> -578.3 | E14: =E12+E13 -> -872.8 | F14: =F12+F13 -> -1219 | G14: =G12+G13 -> -1626.2 | H14: =H12+H13 -> -2103
B15: Net Change in Cash | C15: =C8+C10+C14 -> -142.54061 | D15: =D8+D10+D14 -> -184.47699 | E15: =E8+E10+E14 -> -212.78786 | F15: =F8+F10+F14 -> -248.14613 | G15: =G8+G10+G14 -> -292.76383 | H15: =H8+H10+H14 -> -339.42779

Sheet Balance Sheet
B1: BALANCE SHEET ($M)
B3: Line Item | C3: Day 1 (Opening) | D3: Year 1 | E3: Year 2 | F3: Year 3 | G3: Year 4 | H3: Year 5 | I3: Year 6
B4: Cash & Equivalents | C4: 300 | D4: 296.4 | E4: 198.3 | F4: 92.2 | G4: 0 | H4: 0 | I4: 0
B5: Accounts Receivable | C5: 224 | D5: 238.4 | E5: 249.8 | F5: 262.5 | G5: 276.7 | H5: 292.5 | I5: 310
B6: Inventory | C6: 7014 | D6: 7246.9 | E6: 7572.9 | F6: 7936.2 | G6: 8340.6 | H6: 8790.5 | I6: 9290.8
B7: Other Current Assets | C7: 500 | D7: 511.2 | E7: 512 | F7: 512.8 | G7: 513.5 | H7: 514.2 | I7: 515
B8: Total Current Assets | C8: 8038 | D8: =SUM(D4:D7) -> 8292.9 | E8: =SUM(E4:E7) -> 8533 | F8: =SUM(F4:F7) -> 8803.7 | G8: =SUM(G4:G7) -> 9130.8 | H8: =SUM(H4:H7) -> 9597.2 | I8: =SUM(I4:I7) -> 10115.8
B9: PP&E (net) | C9: 5962 | D9: 6179.5 | E9: 6386.7 | F9: 6582.7 | G9: 6766.4 | H9: 6936.3 | I9: 7090.6
B10: Operating Lease ROU Assets | C10: 8089 | D10: 8089 | E10: 7927.2 | F10: 7768.7 | G10: 7613.3 | H10: 7461 | I10: 7311.8
B11: Goodwill | C11: 30074.1 | D11: 30074.1 | E11: 30074.1 | F11: 30074.1 | G11: 30047 | H11: 29907 | I11: 29746.5
B12: Deferred Financing Fees | C12: 355 | D12: 306.3 | E12: 257.7 | F12: 209 | G12: 160.3 | H12: 111.7 | I12: 63
B13: Other LT Assets | C13: 1487 | D13: 1487 | E13: 1487 | F13: 1487 | G13: 1487 | H13: 1487 | I13: 1487
B14: Total Assets | C14: 54005.1 | D14: =D8+D9+D10+D11+D12+D13 -> 54428.8 | E14: =E8+E9+E10+E11+E12+E13 -> 54665.7 | F14: =F8+F9+F10+F11+F12+F13 -> 54925.2 | G14: =G8+G9+G10+G11+G12+G13 -> 55204.8 | H14: =H8+H9+H10+H11+H12+H13 -> 55500.2 | I14: =I8+I9+I10+I11+I12+I13 -> 55814.7
B15: Accounts Payable | C15: 3856 | D15: 3981.7 | E15: 4160.8 | F15: 4360.4 | G15: 4582.6 | H15: 4829.7 | I15: 5104.6
B16: Accrued Liabilities | C16: 784 | D16: 819.3 | E16: 858.6 | F16: 902.4 | G16: 951.1 | H16: 1005.3 | I16: 1065.7
B17: Current Lease Liabilities | C17: 1002 | D17: 1002 | E17: 1002 | F17: 1002 | G17: 1002 | H17: 1002 | I17: 1002
B18: Other Current Liabilities | C18: 389 | D18: 406.5 | E18: 426 | F18: 447.7 | G18: 471.9 | H18: 498.8 | I18: 528.8
B19: Total Current Liabilities | C19: 6031 | D19: =SUM(D15:D18) -> 6209.5 | E19: =SUM(E15:E18) -> 6447.4 | F19: =SUM(F15:F18) -> 6712.5 | G19: =SUM(G15:G18) -> 7007.6 | H19: =SUM(H15:H18) -> 7335.8 | I19: =SUM(I15:I18) -> 7701.1
B20: Total Debt (new structure) | C20: 21500 | D20: 21191.4 | E20: 20633.1 | F20: 19780.3 | G20: 18581.3 | H20: 16975.1 | I20: 14892.1
B21: LT Operating Lease | C21: 7999 | D21: 7999 | E21: 7759 | F21: 7526.3 | G21: 7300.5 | H21: 7081.5 | I21: 6869
B22: Other LT Liabilities | C22: 1724 | D22: 1801.6 | E22: 1888.1 | F22: 1984.3 | G22: 2091.5 | H22: 2210.7 | I22: 2343.4
B23: Total Liabilities | C23: 37254 | D23: =D19+D20+D21+D22 -> 37201.5 | E23: =E19+E20+E21+E22 -> 36727.6 | F23: =F19+F20+F21+F22 -> 36003.4 | G23: =G19+G20+G21+G22 -> 34980.9 | H23: =H19+H20+H21+H22 -> 33603.1 | I23: =I19+I20+I21+I22 -> 31805.6
B24: Sponsor Equity (Paid-In) | C24: 16751.1 | D24: 16751.1 | E24: 16751.1 | F24: 16751.1 | G24: 16751.1 | H24: 16751.1 | I24: 16751.1
B25: Retained Earnings | C25: 0 | D25: 476.4 | E25: 1187 | F25: 2170.7 | G25: 3472.9 | H25: 5146 | I25: 7258.2
B26: Total Equity | C26: 16751.1 | D26: =D24+D25 -> 17227.5 | E26: =E24+E25 -> 17938.1 | F26: =F24+F25 -> 18921.8 | G26: =G24+G25 -> 20224 | H26: =H24+H25 -> 21897.1 | I26: =I24+I25 -> 24009.3
B27: Total L+E | C27: 54005.1 | D27: =D23+D26 -> 54429 | E27: =E23+E26 -> 54665.7 | F27: =F23+F26 -> 54925.2 | G27: =G23+G26 -> 55204.9 | H27: =H23+H26 -> 55500.2 | I27: =I23+I26 -> 55814.9
B28: BS Check (Assets - L+E) | C28: 0 | D28: =D14-D27 -> -0.2 | E28: =E14-E27 -> 0 | F28: =F14-F27 -> 0 | G28: =G14-G27 -> -0.1 | H28: =H14-H27 -> 0 | I28: =I14-I27 -> -0.2

Sheet Debt Schedule
B1: DEBT SCHEDULE & CASH SWEEP ($M)
B3: CONSOLIDATED DEBT SUMMARY
B4: Metric | C4: Year 1 | D4: Year 2 | E4: Year 3 | F4: Year 4 | G4: Year 5 | H4: Year 6
B5: Beg. Total Debt ($M) | C5: 21500 | D5: 21191.4 | E5: 20633.1 | F5: 19780.3 | G5: 18581.3 | H5: 16975.1
B6: Req. Amortization ($M) | C6: 280 | D6: 280 | E6: 280 | F6: 280 | G6: 280 | H6: 280
B7: Cash Sweep ($M) | C7: 28.6 | D7: 278.3 | E7: 572.8 | F7: 919 | G7: 1326.2 | H7: 1803
B8: Total Repaid ($M) | C8: 308.6 | D8: 558.3 | E8: 852.8 | F8: 1199 | G8: 1606.2 | H8: 2083
B9: End. Total Debt ($M) | C9: =C5-C6-C7 -> 21191.4 | D9: =D5-D6-D7 -> 20633.1 | E9: =E5-E6-E7 -> 19780.3 | F9: =F5-F6-F7 -> 18581.3 | G9: =G5-G6-G7 -> 16975.1 | H9: =H5-H6-H7 -> 14892.1
B10: Cash Interest ($M) | C10: 1805.9 | D10: 1770.4 | E10: 1713.1 | F10: 1629.8 | G10: 1515.9 | H10: 1356.2
B11: DFF Amort ($M) | C11: 48.7 | D11: 48.7 | E11: 48.7 | F11: 48.7 | G11: 48.7 | H11: 48.7
B12: Interest Expense ($M) | C12: 1854.5 | D12: 1819 | E12: 1761.8 | F12: 1678.5 | G12: 1564.6 | H12: 1404.9
B13: Gross Leverage (x) | C13: 5.47 | D13: 4.95 | E13: 4.4 | F13: 3.83 | G13: 3.23 | H13: 2.61
B14: Interest Coverage (x) | C14: 2.09 | D14: 2.29 | E14: 2.55 | F14: 2.89 | G14: 3.36 | H14: 4.06
B15: Revolver ($M) | C15: 471.4 | D15: 193.1 | E15: 0 | F15: 0 | G15: 0 | H15: 0
B16: Term Loan A ($M) | C16: 3800 | D16: 3600 | E16: 3020.3 | F16: 1901.3 | G16: 375.1 | H16: 0
B17: Term Loan B ($M) | C17: 7920 | D17: 7840 | E17: 7760 | F17: 7680 | G17: 7600 | H17: 5892.1
B18: Senior Secured Notes ($M) | C18: 5500 | D18: 5500 | E18: 5500 | F18: 5500 | G18: 5500 | H18: 5500
B19: High Yield Notes ($M) | C19: 3500 | D19: 3500 | E19: 3500 | F19: 3500 | G19: 3500 | H19: 3500
B21: TRANCHE: REVOLVER
B22: Item | C22: Year 1 | D22: Year 2 | E22: Year 3 | F22: Year 4 | G22: Year 5 | H22: Year 6
B23: Beginning Balance ($M) | C23: 500 | D23: 471.4 | E23: 193.1 | F23: 0 | G23: 0 | H23: 0
B24: Required Amort ($M) | C24: 0 | D24: 0 | E24: 0 | F24: 0 | G24: 0 | H24: 0
B25: Cash Sweep ($M) | C25: 28.6 | D25: 278.3 | E25: 193.1 | F25: 0 | G25: 0 | H25: 0
B26: Total Repaid ($M) | C26: 28.6 | D26: 278.3 | E26: 193.1 | F26: 0 | G26: 0 | H26: 0
B27: Ending Balance ($M) | C27: =C23-C24-C25 -> 471.4 | D27: =D23-D24-D25 -> 193.1 | E27: =E23-E24-E25 -> 0 | F27: =F23-F24-F25 -> 0 | G27: =G23-G24-G25 -> 0 | H27: =H23-H24-H25 -> 0
B28: Rate | C28: 7.80% | D28: 7.80% | E28: 7.80% | F28: 7.80% | G28: 7.80% | H28: 7.80%
B29: Interest Expense ($M) | C29: 37.9 | D29: 25.9 | E29: 7.5 | F29: 0 | G29: 0 | H29: 0
B30: DFF Amort ($M) | C30: 0.5 | D30: 0.5 | E30: 0.5 | F30: 0.5 | G30: 0.5 | H30: 0.5
B32: TRANCHE: TERM LOAN A
B33: Item | C33: Year 1 | D33: Year 2 | E33: Year 3 | F33: Year 4 | G33: Year 5 | H33: Year 6
B34: Beginning Balance ($M) | C34: 4000 | D34: 3800 | E34: 3600 | F34: 3020.3 | G34: 1901.3 | H34: 375.1
B35: Required Amort ($M) | C35: 200 | D35: 200 | E35: 200 | F35: 200 | G35: 200 | H35: 200
B36: Cash Sweep ($M) | C36: 0 | D36: 0 | E36: 379.7 | F36: 919 | G36: 1326.2 | H36: 175.1
B37: Total Repaid ($M) | C37: 200 | D37: 200 | E37: 579.7 | F37: 1119 | G37: 1526.2 | H37: 375.1
B38: Ending Balance ($M) | C38: =C34-C35-C36 -> 3800 | D38: =D34-D35-D36 -> 3600 | E38: =E34-E35-E36 -> 3020.3 | F38: =F34-F35-F36 -> 1901.3 | G38: =G34-G35-G36 -> 375.1 | H38: =H34-H35-H36 -> 0
B39: Rate | C39: 8.05% | D39: 8.05% | E39: 8.05% | F39: 8.05% | G39: 8.05% | H39: 8.05%
B40: Interest Expense ($M) | C40: 313.9 | D40: 297.9 | E40: 266.5 | F40: 198.1 | G40: 91.6 | H40: 15.1
B41: DFF Amort ($M) | C41: 8 | D41: 8 | E41: 8 | F41: 8 | G41: 8 | H41: 8
B43: TRANCHE: TERM LOAN B
B44: Item | C44: Year 1 | D44: Year 2 | E44: Year 3 | F44: Year 4 | G44: Year 5 | H44: Year 6
...

Sheet Returns & Value Bridge
B1: RETURNS ANALYSIS & VALUE ATTRIBUTION ($M)
B3: RETURNS SUMMARY
B4: Equity Invested ($M) | C4: 16751.1
B5: Exit Equity ($M) | C5: 56480.4
B6: IRR | C6: 0.22454808
B7: MOIC | C7: 3.3717476
B8: Hold Period (years) | C8: 6
B9: Entry EV ($M) | C9: 37107
B10: Entry EV/EBITDA (x) | C10: 10.5
B11: Entry EBITDA ($M) | C11: 3534
B12: Entry Net Debt ($M) | C12: 21200
B13: Exit EV ($M) | C13: 71372.5
B14: Exit EV/EBITDA (x) | C14: 12.5
B15: Exit EBITDA ($M) | C15: 5709.8
B16: Exit Net Debt ($M) | C16: 14892.1
B18: VALUE CREATION BRIDGE ($M)
B19: Entry Equity Value ($M) | C19: 15907
B20: (+) EBITDA Growth | C20: 22845.9
B21: (+) Multiple Expansion / (Contraction) | C21: 11419.6
B22: (+) Debt Paydown (Deleveraging) | C22: 6307.9
B23: Total Value Creation ($M) | C23: =C20+C21+C22 -> 40573.4
B24: Exit Equity Value ($M) | C24: =C19+C23 -> 56480.4
B26: CASH FLOW TO EQUITY ($M)
B27: Year | C27: Cash Flow ($M)
B28: Year 0 (Equity In) | C28: -16751.1
B29: Year 1 | C29: 0
B30: Year 2 | C30: 0
B31: Year 3 | C31: 0
B32: Year 4 | C32: 0
B33: Year 5 | C33: 0
B34: Year 6 (Exit) | C34: 56480.4

Sheet Credit Metrics
B1: CREDIT METRICS & COVENANT ANALYSIS
B3: YEAR-BY-YEAR CREDIT METRICS
B4: Metric | C4: Year 1 | D4: Year 2 | E4: Year 3 | F4: Year 4 | G4: Year 5 | H4: Year 6
B5: Revenue ($M) | C5: 39547 | D5: 41445.2 | E5: 43558.9 | F5: 45911.1 | G5: 48528.1 | H5: 51439.7
B6: EBITDA ($M) | C6: 3875.6 | D6: 4169.4 | E6: 4495.3 | F6: 4857.4 | G6: 5260.4 | H6: 5709.8
B7: EBITDA Margin | C7: 0.097999848 | D7: 0.10060031 | E7: 0.10320049 | F7: 0.10580012 | G7: 0.10839905 | H7: 0.11099987
B8: Total Debt ($M) | C8: 21191.4 | D8: 20633.1 | E8: 19780.3 | F8: 18581.3 | G8: 16975.1 | H8: 14892.1
B9: Net Debt ($M) | C9: 20895 | D9: 20434.8 | E9: 19688.1 | F9: 18581.3 | G9: 16975.1 | H9: 14892.1
B10: Gross Leverage (x) | C10: 5.47 | D10: 4.95 | E10: 4.4 | F10: 3.83 | G10: 3.23 | H10: 2.61
B11: Net Leverage (x) | C11: 5.39 | D11: 4.9 | E11: 4.38 | F11: 3.83 | G11: 3.23 | H11: 2.61
B12: Cash Interest ($M) | C12: 1805.9 | D12: 1770.4 | E12: 1713.1 | F12: 1629.8 | G12: 1515.9 | H12: 1356.2
B13: Interest Coverage (x) | C13: 2.15 | D13: 2.36 | E13: 2.62 | F13: 2.98 | G13: 3.47 | H13: 4.21
B14: Fixed Charge Coverage (x) | C14: 1.86 | D14: 2.03 | E14: 2.26 | F14: 2.54 | G14: 2.93 | H14: 3.49
B15: DSCR (x) | C15: 1 | D15: 1.15 | E15: 1.35 | F15: 1.62 | G15: 2 | H15: 2.57
B16: Operating CF ($M) | C16: 1807.3 | D16: 2030.8 | E16: 2315.1 | F16: 2646.6 | G16: 3031.9 | H16: 3486.8
... B19: CapEx / Revenue | C19: 0.040999317 | D19: 0.039500352 | E19: 0.037999123 | F19: 0.036500977 | G19: 0.03500034 | H19: 0.033499418
B20: Implied Rating | C20: BB/Ba2 | D20: BB/Ba2 | E20: BB+/Ba1 | F20: BB+/Ba1 | G20: BBB-/Baa3 | H20: BBB/Baa2
B22: COVENANT COMPLIANCE & HEADROOM
B23: Covenant Metric | C23: Year 1 | D23: Year 2 | E23: Year 3 | F23: Year 4 | G23: Year 5 | H23: Year 6
B24: Gross Leverage | C24: 5.47 | D24: 4.95 | E24: 4.4 | F24: 3.83 | G24: 3.23 | H24: 2.61
B25: Max Leverage Covenant | C25: 6.5 | D25: 6 | E25: 5.5 | F25: 5 | G25: 4.5 | H25: 4
B26: Leverage Headroom (x) | C26: 1.03 | D26: 1.05 | E26: 1.1 | F26: 1.17 | G26: 1.27 | H26: 1.39
B27: In Compliance (Leverage) | C27: YES | D27: YES | E27: YES | F27: YES | G27: YES | H27: YES
B28: Interest Coverage | C28: 2.15 | D28: 2.36 | E28: 2.62 | F28: 2.98 | G28: 3.47 | H28: 4.21
B29: Min Coverage Covenant | C29: 2 | D29: 2 | E29: 2.25 | F29: 2.25 | G29: 2.5 | H29: 2.5
B30: Coverage Headroom (x) | C30: 0.15 | D30: 0.36 | E30: 0.37 | F30: 0.73 | G30: 0.97 | H30: 1.71
B31: In Compliance (Coverage) | C31: YES | D31: YES | E31: YES | F31: YES | G31: YES | H31: YES

Sheet Scenario Analysis
B1: SCENARIO ANALYSIS — BULL / BASE / BEAR
B3: RETURNS COMPARISON
B4: Metric | C4: Bear | D4: Base | E4: Bull
B5: IRR | C5: 10.3% | D5: 22.5% | E5: 31.4%
B6: MOIC | C6: 1.80x | D6: 3.37x | E6: 5.15x
B7: Entry EV ($M) | C7: $37,107 | D7: $37,107 | E7: $37,107
B8: Exit EV ($M) | C8: $48,494 | D8: $71,372 | E8: $97,559
B9: Exit Equity ($M) | C9: $30,149 | D9: $56,480 | E9: $86,228
B10: Equity Invested ($M) | C10: $16,751 | D10: $16,751 | E10: $16,751
B12: DETAILED COMPARISON
B13: Metric | C13: Bear | D13: Base | E13: Bull
B14: Bear | C14: 2.7% | D14: 9.9% | E14: 11.0x | F14: $37,107 | G14: 6.1x | H14: $48,494 | I14: $18,344 | J14: $30,149 | K14: 10.3% | L14: 1.80x | M14: 4.16x
B15: Base | C15: 5.2% | D15: 11.1% | E15: 12.5x | F15: $37,107 | G15: 6.1x | H15: $71,372 | I15: $14,892 | J15: $56,480 | K15: 22.5% | L15: 3.37x | M15: 2.61x
B16: Bull | C16: 7.2% | D16: 12.1% | E16: 14.0x | F16: $37,107 | G16: 6.1x | H16: $97,559 | I16: $11,331 | J16: $86,228 | K16: 31.4% | L16: 5.15x | M16: 1.63x
