Workbook

Sheet Cover
B2: LEVERAGED BUYOUT ANALYSIS Dollar General Corporation (NYSE: DG)
B5: Discount Retail | ~20,000 Stores | Prepared: February 26, 2026
B7: KEY RETURNS SUMMARY
B8: IRR | C8: 20.1%
B9: MOIC | C9: 2.49x
B10: Entry EV ($M) | C10: $37,107
B11: Equity Invested ($M) | C11: $17,244
B12: Exit EV ($M) | C12: $58,629
B13: Exit Equity ($M) | C13: $42,997
B14: Hold Period | C14: 5 years
B15: Entry EV/EBITDA | C15: 10.5x
B16: Exit EV/EBITDA | C16: 10.5x
B17: Entry Leverage | C17: 5.9x
B19: TRANSACTION OVERVIEW
B20: Target | C20: Dollar General Corporation
B21: Sector | C21: Consumer Discretionary — Discount Retail
B22: LTM Revenue ($M) | C22: $37,844
B23: LTM EBITDA ($M) | C23: $3,534
B24: LTM EBITDA Margin | C24: 9.3%
B25: Total New Debt ($M) | C25: $21,000
B26: Sponsor Equity ($M) | C26: $17,244
B27: Equity / Total Cap. | C27: 45.1%
B30: CONFIDENTIAL — For Discussion Purposes Only. All values USD millions unless noted. ‡ Interest Expense is computed by an iterative debt engine and is a fixed input to the P&L.

Sheet Assumptions
B1: DEAL ASSUMPTIONS
B3: 1. ENTRY / TRANSACTION
B4: LTM EBITDA ($M) | C4: 3534
B5: Entry EV/EBITDA (x) | C5: 10.5
B6: Entry EV ($M) | C6: 37107
B7: Existing Net Debt ($M) | C7: 6512
B8: Total New Debt ($M) | C8: 21000
B9: Sponsor Equity ($M) | C9: 17243.589
B10: Entry Gross Leverage (x) | C10: 5.942275
B11: Hold Period (years) | C11: 5
B12: Exit EV/EBITDA (x) | C12: 10.5
B13: Tax Rate | C13: 0.228
B14: Cash Sweep (%) | C14: 1
B15: Min Cash Balance ($M) | C15: 300
B17: 2. DEBT STRUCTURE
B18: Tranche | C18: Principal ($M) | D18: Rate Type | E18: All-In Rate | F18: Term (yrs) | G18: Amort % | H18: OID %
B19: Revolver | C19: 500 | D19: SOFR + 2% | E19: 0.078 | F19: 5 | G19: 0 | H19: 0.005
B20: Term Loan A | C20: 4000 | D20: SOFR + 3% | E20: 0.0805 | F20: 5 | G20: 0.05 | H20: 0.01
B21: Term Loan B | C21: 8000 | D21: SOFR + 4% | E21: 0.093 | F21: 7 | G21: 0.01 | H21: 0.02
B22: Senior Secured Notes | C22: 5000 | D22: Fixed | E22: 0.0725 | F22: 8 | G22: 0 | H22: 0.015
B23: High Yield Notes | C23: 3500 | D23: Fixed | E23: 0.09 | F23: 10 | G23: 0 | H23: 0.02
B25: 3. OPERATING PROJECTIONS (BY YEAR)
B26: Driver | C26: Year 1 | D26: Year 2 | E26: Year 3 | F26: Year 4 | G26: Year 5
B27: Revenue Growth (%) | C27: 0.04 | D27: 0.04375 | E27: 0.0475 | F27: 0.05125 | G27: 0.055
B28: EBITDA Margin (%) | C28: 0.098 | D28: 0.10275 | E28: 0.1075 | F28: 0.11225 | G28: 0.117
B29: D&A (% Revenue) | C29: 0.0355 | D29: 0.0345 | E29: 0.0335 | F29: 0.0325 | G29: 0.0315
B30: CapEx (% Revenue) | C30: 0.041 | D30: 0.0395 | E30: 0.038 | F30: 0.0365 | G30: 0.035

Sheet Sources & Uses
B1: SOURCES & USES OF FUNDS
B3: SOURCES | C3: Amount ($M) | D3: % Total | F3: USES | G3: Amount ($M) | H3: % Total
B4: Revolver (SOFR+250bps, 5yr) | C4: 500 | D4: 1.3% | F4: Purchase Equity (EV – Net Debt) | G4: 30595 | H4: 80.0%
B5: Term Loan A (SOFR+275bps, 5yr) | C5: 4000 | D5: 10.5% | F5: Repay Existing Gross Debt | G5: 6797 | H5: 17.8%
B6: Term Loan B (SOFR+400bps, 7yr) | C6: 8000 | D6: 20.9% | F6: M&A Advisory & Legal Fees | G6: 204.1 | H6: 0.5%
B7: Senior Secured Notes (7.25% fixed, 8yr) | C7: 5000 | D7: 13.1% | F7: Financing Fees / OID | G7: 347.5 | H7: 0.9%
B8: High Yield Notes (9.00% fixed, 10yr) | C8: 3500 | D8: 9.2% | F8: Cash to Balance Sheet | G8: 300 | H8: 0.8%
B9: Sponsor Equity | C9: 17243.589 | D9: 45.1% | F9: Total Uses | G9: =SUM(G4:G8) | H9: 100.0%
B10: Total Sources | C10: =SUM(C4:C9) | D10: 100.0%
B13: Entry Leverage: 5.9x | Net Leverage: 5.9x | Equity / Total Cap: 45.1%

Sheet Income Statement
B1: PROJECTED INCOME STATEMENT ($M)
B3: Line Item | C3: Year 1 | D3: Year 2 | E3: Year 3 | F3: Year 4 | G3: Year 5
B4: REVENUE & MARGIN DRIVERS ← editable inputs
B5: Entry LTM Revenue ($M) | C5: 37844
B6: Revenue Growth (%) | C6: 0.04 | D6: 0.04375 | E6: 0.0475 | F6: 0.05125 | G6: 0.055
B7: EBITDA Margin (%) | C7: 0.098 | D7: 0.10275 | E7: 0.1075 | F7: 0.11225 | G7: 0.117
B8: D&A (% Revenue) | C8: 0.0355 | D8: 0.0345 | E8: 0.0335 | F8: 0.0325 | G8: 0.0315
B9: Gross Margin (%) | C9: 0.304 | D9: 0.306 | E9: 0.308 | F9: 0.31 | G9: 0.312
B10: Tax Rate | C10: 0.228 | D10: =$C$10 | E10: =$C$10 | F10: =$C$10 | G10: =$C$10
B11: Annual Mgmt Fee ($M) | C11: 20 | D11: 20 | E11: 20 | F11: 20 | G11: 20
B13: PROJECTED P&L (formulas reference driver block above)
B14: Revenue | C14: =$C$5*(1+C6) | D14: =C14*(1+D6) | E14: =D14*(1+E6) | F14: =E14*(1+F6) | G14: =F14*(1+G6)
B15: COGS | C15: =C14*(1-C9) | D15: =D14*(1-D9) | E15: =E14*(1-E9) | F15: =F14*(1-F9) | G15: =G14*(1-G9)
B16: Gross Profit | C16: =C14-C15 | D16: =D14-D15 | E16: =E14-E15 | F16: =F14-F15 | G16: =G14-G15
B17: Gross Margin | C17: =C16/C14 | D17: =D16/D14 | E17: =E16/E14 | F17: =F16/F14 | G17: =G16/G14
B18: EBITDA | C18: =C14*C7 | D18: =D14*D7 | E18: =E14*E7 | F18: =F14*F7 | G18: =G14*G7
B19: EBITDA Margin | C19: =C18/C14 | D19: =D18/D14 | E19: =E18/E14 | F19: =F18/F14 | G19: =G18/G14
B20: Mgmt Fee | C20: =C11 | D20: =D11 | E20: =E11 | F20: =F11 | G20: =G11
B21: Adj EBITDA | C21: =C18+C20 | D21: =D18+D20 | E21: =E18+E20 | F21: =F18+F20 | G21: =G18+G20
B22: D&A | C22: =C14*C8 | D22: =D14*D8 | E22: =E14*E8 | F22: =F14*F8 | G22: =G14*G8
B23: EBIT | C23: =C18-C22 | D23: =D18-D22 | E23: =E18-E22 | F23: =F18-F22 | G23: =G18-G22
B24: Interest Expense ‡ | C24: 1816.6 | D24: 1777 | E24: 1710.2 | F24: 1610.8 | G24: 1470.4
B25: EBT | C25: =C23-C24 | D25: =D23-D24 | E25: =E23-E24 | F25: =F23-F24 | G25: =G23-G24
B26: Tax | C26: =MAX(0,C25)*$C$10 | D26: =MAX(0,D25)*$C$10 | E26: =MAX(0,E25)*$C$10 | F26: =MAX(0,F25)*$C$10 | G26: =MAX(0,G25)*$C$10
B27: Net Income | C27: =C25-C26 | D27: =D25-D26 | E27: =E25-E26 | F27: =F25-F26 | G27: =G25-G26
B29: ‡ Interest Expense is computed by an iterative cash-sweep debt model and cannot be replicated by a simple Excel formula. All other P&L line items are formula-driven.

Sheet Cash Flow Statement
B1: PROJECTED CASH FLOW STATEMENT ($M)
B3: Line Item | C3: Year 1 | D3: Year 2 | E3: Year 3 | F3: Year 4 | G3: Year 5
B4: Net Income | C4: ='Income Statement'!C27 | D4: ='Income Statement'!D27 | E4: ='Income Statement'!E27 | F4: ='Income Statement'!F27 | G4: ='Income Statement'!G27
B5: (+) D&A | C5: ='Income Statement'!C22 | D5: ='Income Statement'!D22 | E5: ='Income Statement'!E22 | F5: ='Income Statement'!F22 | G5: ='Income Statement'!G22
B6: (+) DFF Amort | C6: 47.7 | D6: 47.7 | E6: 47.7 | F6: 47.7 | G6: 47.7
B7: Δ NWC | C7: -104.9 | D7: -142.8 | E7: -162.2 | F7: -183.6 | G7: -207.3
B8: Operating CF | C8: =C4+C5+C6+C7 | D8: =D4+D5+D6+D7 | E8: =E4+E5+E6+E7 | F8: =F4+F5+F6+F7 | G8: =G4+G5+G6+G7
B9: (-) CapEx | C9: =-'Income Statement'!C14*0.041 | D9: =-'Income Statement'!D14*0.0395 | E9: =-'Income Statement'!E14*0.038 | F9: =-'Income Statement'!F14*0.036500000000000005 | G9: =-'Income Statement'!G14*0.035
B10: Investing CF | C10: =C9 | D10: =D9 | E10: =E9 | F10: =F9 | G10: =G9
B11: Free Cash Flow | C11: =C8+C10 | D11: =D8+D10 | E11: =E8+E10 | F11: =F8+F10 | G11: =G8+G10
B12: (-) Debt Repaid | C12: -329 | D12: -641 | E12: -1008.3 | F12: -1439.5 | G12: -1950.6
B13: (-) Mgmt Fee | C13: -20 | D13: -20 | E13: -20 | F13: -20 | G13: -20
B14: Financing CF | C14: =C12+C13 | D14: =D12+D13 | E14: =E12+E13 | F14: =F12+F13 | G14: =G12+G13
B15: Net Change in Cash | C15: =C8+C10+C14 | D15: =D8+D10+D14 | E15: =E8+E10+E14 | F15: =F8+F10+F14 | G15: =G8+G10+G14

Sheet Balance Sheet
B1: BALANCE SHEET ($M)
B3: Line Item | C3: Day 1 (Opening) | D3: Year 1 | E3: Year 2 | F3: Year 3 | G3: Year 4 | H3: Year 5
B4: Cash & Equivalents | C4: 300 | D4: 299.9 | E4: 203.7 | F4: 99.5 | G4: 0 | H4: 0
B5: Accounts Receivable | C5: 224 | D5: 237.2 | E5: 247.6 | F5: 259.4 | G5: 272.7 | H5: 287.7
B6: Inventory | C6: 7014 | D6: 7212.2 | E6: 7506.1 | F6: 7840 | G6: 8218 | H6: 8644.9
B7: Other Current Assets | C7: 500 | D7: 510 | E7: 510.9 | F7: 511.9 | G7: 512.8 | H7: 513.8
B8: Total Current Assets | C8: 8038 | D8: =SUM(D4:D7) | E8: =SUM(E4:E7) | F8: =SUM(F4:F7) | G8: =SUM(G4:G7) | H8: =SUM(H4:H7)
B9: PP&E (net) | C9: 5962 | D9: 6178.5 | E9: 6383.9 | F9: 6577.6 | G9: 6758.5 | H9: 6925.6
B10: Operating Lease ROU Assets | C10: 8089 | D10: 8089 | E10: 7927.2 | F10: 7768.7 | G10: 7613.3 | H10: 7461
B11: Goodwill | C11: 30074.1 | D11: 30074.1 | E11: 30074.1 | F11: 30074.1 | G11: 30056.3 | H11: 29916.7
B12: Deferred Financing Fees | C12: 347.5 | D12: 299.8 | E12: 252 | F12: 204.3 | G12: 156.6 | H12: 108.8
B13: Other LT Assets | C13: 1487 | D13: 1487 | E13: 1487 | F13: 1487 | G13: 1487 | H13: 1487
B14: Total Assets | C14: 53997.6 | D14: =D8+D9+D10+D11+D12+D13 | E14: =E8+E9+E10+E11+E12+E13 | F14: =F8+F9+F10+F11+F12+F13 | G14: =G8+G9+G10+G11+G12+G13 | H14: =H8+H9+H10+H11+H12+H13
B15: Accounts Payable | C15: 3856 | D15: 3962.6 | E15: 4124.1 | F15: 4307.5 | G15: 4515.2 | H15: 4749.7
B16: Accrued Liabilities | C16: 784 | D16: 815.4 | E16: 851 | F16: 891.5 | G16: 937.1 | H16: 988.7
B17: Current Lease Liabilities | C17: 1002 | D17: 1002 | E17: 1002 | F17: 1002 | G17: 1002 | H17: 1002
B18: Other Current Liabilities | C18: 389 | D18: 404.6 | E18: 422.3 | F18: 442.3 | G18: 465 | H18: 490.6
B19: Total Current Liabilities | C19: 6031 | D19: =SUM(D15:D18) | E19: =SUM(E15:E18) | F19: =SUM(F15:F18) | G19: =SUM(G15:G18) | H19: =SUM(H15:H18)
B20: Total Debt (new structure) | C20: 21000 | D20: 20671 | E20: 20030 | F20: 19021.8 | G20: 17582.3 | H20: 15631.7
B21: LT Operating Lease | C21: 7999 | D21: 7999 | E21: 7759 | F21: 7526.3 | G21: 7300.5 | H21: 7081.5
B22: Other LT Liabilities | C22: 1724 | D22: 1793 | E22: 1871.4 | F22: 1960.3 | G22: 2060.8 | H22: 2174.1
B23: Total Liabilities | C23: 36754 | D23: =D19+D20+D21+D22 | E23: =E19+E20+E21+E22 | F23: =F19+F20+F21+F22 | G23: =G19+G20+G21+G22 | H23: =H19+H20+H21+H22
B24: Sponsor Equity (Paid-In) | C24: 17243.6 | D24: 17243.6 | E24: 17243.6 | F24: 17243.6 | G24: 17243.6 | H24: 17243.6
B25: Retained Earnings | C25: 0 | D25: 496.6 | E25: 1289.2 | F25: 2427.2 | G25: 3968.7 | H25: 5983.6
B26: Total Equity | C26: 17243.6 | D26: =D24+D25 | E26: =E24+E25 | F26: =F24+F25 | G26: =G24+G25 | H26: =H24+H25
B27: Total L+E | C27: 53997.6 | D27: =D23+D26 | E27: =E23+E26 | F27: =F23+F26 | G27: =G23+G26 | H27: =H23+H26
B28: BS Check (Assets - L+E) | C28: 0 | D28: =D14-D27 | E28: =E14-E27 | F28: =F14-F27 | G28: =G14-G27 | H28: =H14-H27

Sheet Debt Schedule
B1: DEBT SCHEDULE & CASH SWEEP ($M)
B3: CONSOLIDATED DEBT SUMMARY
B4: Metric | C4: Year 1 | D4: Year 2 | E4: Year 3 | F4: Year 4 | G4: Year 5
B5: Beg. Total Debt ($M) | C5: 21000 | D5: 20671 | E5: 20030 | F5: 19021.8 | G5: 17582.3
B6: Req. Amortization ($M) | C6: 280 | D6: 280 | E6: 280 | F6: 280 | G6: 280
B7: Cash Sweep ($M) | C7: 49 | D7: 361 | E7: 728.3 | F7: 1159.5 | G7: 1670.6
B8: Total Repaid ($M) | C8: 329 | D8: 641 | E8: 1008.3 | F8: 1439.5 | G8: 1950.6
B9: End. Total Debt ($M) | C9: =C5-C6-C7 | D9: =D5-D6-D7 | E9: =E5-E6-E7 | F9: =F5-F6-F7 | G9: =G5-G6-G7
B10: Cash Interest ($M) | C10: 1768.8 | D10: 1729.3 | E10: 1662.5 | F10: 1563.1 | G10: 1422.7
B11: DFF Amort ($M) | C11: 47.7 | D11: 47.7 | E11: 47.7 | F11: 47.7 | G11: 47.7
B12: Interest Expense ($M) | C12: 1816.6 | D12: 1777 | E12: 1710.2 | F12: 1610.8 | G12: 1470.4
B13: Gross Leverage (x) | C13: 5.36 | D13: 4.75 | E13: 4.11 | F13: 3.46 | G13: 2.8
B14: Interest Coverage (x) | C14: 2.12 | D14: 2.38 | E14: 2.7 | F14: 3.15 | G14: 3.8
B15: Revolver ($M) | C15: 451 | D15: 90 | E15: 0 | F15: 0 | G15: 0
B16: Term Loan A ($M) | C16: 3800 | D16: 3600 | E16: 2761.8 | F16: 1402.3 | G16: 0
B17: Term Loan B ($M) | C17: 7920 | D17: 7840 | E17: 7760 | F17: 7680 | G17: 7131.7
B18: Senior Secured Notes ($M) | C18: 5000 | D18: 5000 | E18: 5000 | F18: 5000 | G18: 5000
B19: High Yield Notes ($M) | C19: 3500 | D19: 3500 | E19: 3500 | F19: 3500 | G19: 3500
B21: TRANCHE: REVOLVER
B22: Item | C22: Year 1 | D22: Year 2 | E22: Year 3 | F22: Year 4 | G22: Year 5
B23: Beginning Balance ($M) | C23: 500 | D23: 451 | E23: 90 | F23: 0 | G23: 0
B24: Required Amort ($M) | C24: 0 | D24: 0 | E24: 0 | F24: 0 | G24: 0
B25: Cash Sweep ($M) | C25: 49 | D25: 361 | E25: 90 | F25: 0 | G25: 0
B26: Total Repaid ($M) | C26: 49 | D26: 361 | E26: 90 | F26: 0 | G26: 0
B27: Ending Balance ($M) | C27: =C23-C24-C25 | D27: =D23-D24-D25 | E27: =E23-E24-E25 | F27: =F23-F24-F25 | G27: =G23-G24-G25
B28: Rate | C28: 7.80% | D28: 7.80% | E28: 7.80% | F28: 7.80% | G28: 7.80%
B29: Interest Expense ($M) | C29: 37.1 | D29: 21.1 | E29: 3.5 | F29: 0 | G29: 0
B30: DFF Amort ($M) | C30: 0.5 | D30: 0.5 | E30: 0.5 | F30: 0.5 | G30: 0.5
B32: TRANCHE: TERM LOAN A
B33: Item | C33: Year 1 | D33: Year 2 | E33: Year 3 | F33: Year 4 | G33: Year 5
B34: Beginning Balance ($M) | C34: 4000 | D34: 3800 | E34: 3600 | F34: 2761.8 | G34: 1402.3
B35: Required Amort ($M) | C35: 200 | D35: 200 | E35: 200 | F35: 200 | G35: 200
B36: Cash Sweep ($M) | C36: 0 | D36: 0 | E36: 638.2 | F36: 1159.5 | G36: 1202.3
B37: Total Repaid ($M) | C37: 200 | D37: 200 | E37: 838.2 | F37: 1359.5 | G37: 1402.3
B38: Ending Balance ($M) | C38: =C34-C35-C36 | D38: =D34-D35-D36 | E38: =E34-E35-E36 | F38: =F34-F35-F36 | G38: =G34-G35-G36
B39: Rate | C39: 8.05% | D39: 8.05% | E39: 8.05% | F39: 8.05% | G39: 8.05%
B40: Interest Expense ($M) | C40: 313.9 | D40: 297.9 | E40: 256.1 | F40: 167.6 | G40: 56.4
B41: DFF Amort ($M) | C41: 8 | D41: 8 | E41: 8 | F41: 8 | G41: 8
B43: TRANCHE: TERM LOAN B
B44: Item | C44: Year 1 | D44: Year 2 | E44: Year 3 | F44: Year 4 | G44: Year 5
...

Sheet Returns & Value Bridge
B1: RETURNS ANALYSIS & VALUE ATTRIBUTION ($M)
B3: RETURNS SUMMARY
B4: Equity Invested ($M) | C4: 17243.6
B5: Exit Equity ($M) | C5: 42997.2
B6: IRR | C6: 0.20050086
B7: MOIC | C7: 2.4935173
B8: Hold Period (years) | C8: 5
B9: Entry EV ($M) | C9: 37107
B10: Entry EV/EBITDA (x) | C10: 10.5
B11: Entry EBITDA ($M) | C11: 3534
B12: Entry Net Debt ($M) | C12: 20700
B13: Exit EV ($M) | C13: 58628.8
B14: Exit EV/EBITDA (x) | C14: 10.5
B15: Exit EBITDA ($M) | C15: 5583.7
B16: Exit Net Debt ($M) | C16: 15631.7
B18: VALUE CREATION BRIDGE ($M)
B19: Entry Equity Value ($M) | C19: 16407
B20: (+) EBITDA Growth | C20: 21521.8
B21: (+) Multiple Expansion / (Contraction) | C21: 0
B22: (+) Debt Paydown (Deleveraging) | C22: 5068.3
B23: Total Value Creation ($M) | C23: =C20+C21+C22
B24: Exit Equity Value ($M) | C24: =C19+C23
B26: CASH FLOW TO EQUITY ($M)
B27: Year | C27: Cash Flow ($M)
B28: Year 0 (Equity In) | C28: -17243.6
B29: Year 1 | C29: 0
B30: Year 2 | C30: 0
B31: Year 3 | C31: 0
B32: Year 4 | C32: 0
B33: Year 5 (Exit) | C33: 42997.2

Sheet Credit Metrics
B1: CREDIT METRICS & COVENANT ANALYSIS
B3: YEAR-BY-YEAR CREDIT METRICS
B4: Metric | C4: Year 1 | D4: Year 2 | E4: Year 3 | F4: Year 4 | G4: Year 5
B5: Revenue ($M) | C5: 39357.8 | D5: 41079.7 | E5: 43030.9 | F5: 45236.3 | G5: 47724.3
B6: EBITDA ($M) | C6: 3857.1 | D6: 4220.9 | E6: 4625.8 | F6: 5077.8 | G6: 5583.7
B7: EBITDA Margin | C7: 0.098000905 | D7: 0.10274905 | E7: 0.10749949 | F7: 0.11225056 | G7: 0.1169991
B8: Total Debt ($M) | C8: 20671 | D8: 20030 | E8: 19021.8 | F8: 17582.3 | G8: 15631.7
B9: Net Debt ($M) | C9: 20371.1 | D9: 19826.3 | E9: 18922.3 | F9: 17582.3 | G9: 15631.7
B10: Gross Leverage (x) | C10: 5.36 | D10: 4.75 | E10: 4.11 | F10: 3.46 | G10: 2.8
B11: Net Leverage (x) | C11: 5.28 | D11: 4.7 | E11: 4.09 | F11: 3.46 | G11: 2.8
B12: Cash Interest ($M) | C12: 1768.8 | D12: 1729.3 | E12: 1662.5 | F12: 1563.1 | G12: 1422.7
B13: Interest Coverage (x) | C13: 2.18 | D13: 2.44 | E13: 2.78 | F13: 3.25 | G13: 3.92
B14: Fixed Charge Coverage (x) | C14: 1.88 | D14: 2.1 | E14: 2.38 | F14: 2.76 | G14: 3.28
B15: DSCR (x) | C15: 1.04 | D15: 1.22 | E15: 1.48 | F15: 1.84 | G15: 2.36
B16: Operating CF ($M) | C16: 1836.7 | D16: 2114.7 | E16: 2465 | F16: 2875.8 | G16: 3358.6
... B19: CapEx / Revenue | C19: 0.041000767 | D19: 0.039498828 | E19: 0.0380006 | F19: 0.036499448 | G19: 0.035001037
B20: Implied Rating | C20: BB/Ba2 | D20: BB/Ba2 | E20: BB+/Ba1 | F20: BBB-/Baa3 | G20: BBB/Baa2
B22: COVENANT COMPLIANCE & HEADROOM
B23: Covenant Metric | C23: Year 1 | D23: Year 2 | E23: Year 3 | F23: Year 4 | G23: Year 5
B24: Gross Leverage | C24: 5.36 | D24: 4.75 | E24: 4.11 | F24: 3.46 | G24: 2.8
B25: Max Leverage Covenant | C25: 6.5 | D25: 6 | E25: 5.5 | F25: 5 | G25: 4.5
B26: Leverage Headroom (x) | C26: 1.14 | D26: 1.25 | E26: 1.39 | F26: 1.54 | G26: 1.7
B27: In Compliance (Leverage) | C27: YES | D27: YES | E27: YES | F27: YES | G27: YES
B28: Interest Coverage | C28: 2.18 | D28: 2.44 | E28: 2.78 | F28: 3.25 | G28: 3.92
B29: Min Coverage Covenant | C29: 2 | D29: 2 | E29: 2.25 | F29: 2.25 | G29: 2.5
B30: Coverage Headroom (x) | C30: 0.18 | D30: 0.44 | E30: 0.53 | F30: 1 | G30: 1.42
B31: In Compliance (Coverage) | C31: YES | D31: YES | E31: YES | F31: YES | G31: YES

Sheet Scenario Analysis
B1: SCENARIO ANALYSIS — BULL / BASE / BEAR
B3: RETURNS COMPARISON
B4: Metric | C4: Bear | D4: Base | E4: Bull
B5: IRR | C5: 4.7% | D5: 20.1% | E5: 31.2%
B6: MOIC | C6: 1.26x | D6: 2.49x | E6: 3.89x
B7: Entry EV ($M) | C7: $37,107 | D7: $37,107 | E7: $37,107
B8: Exit EV ($M) | C8: $39,968 | D8: $58,629 | E8: $79,945
B9: Exit Equity ($M) | C9: $21,741 | D9: $42,997 | E9: $67,063
B10: Equity Invested ($M) | C10: $17,244 | D10: $17,244 | E10: $17,244
B12: DETAILED COMPARISON
B13: Metric | C13: Bear | D13: Base | E13: Bull
B14: Bear | C14: 2.2% | D14: 10.5% | E14: 9.0x | F14: $37,107 | G14: 5.9x | H14: $39,968 | I14: $18,227 | J14: $21,741 | K14: 4.7% | L14: 1.26x | M14: 4.10x
B15: Base | C15: 4.7% | D15: 11.7% | E15: 10.5x | F15: $37,107 | G15: 5.9x | H15: $58,629 | I15: $15,632 | J15: $42,997 | K15: 20.1% | L15: 2.49x | M15: 2.80x
B16: Bull | C16: 6.7% | D16: 12.7% | E16: 12.0x | F16: $37,107 | G16: 5.9x | H16: $79,945 | I16: $12,882 | J16: $67,063 | K16: 31.2% | L16: 3.89x | M16: 1.93x
